<?xml version="1.0"?>
<!-- Copyright (c) 2016 The UUV Simulator Authors.
     All rights reserved.

     Licensed under the Apache License, Version 2.0 (the "License");
     you may not use this file except in compliance with the License.
     You may obtain a copy of the License at

       http://www.apache.org/licenses/LICENSE-2.0

     Unless required by applicable law or agreed to in writing, software
     distributed under the License is distributed on an "AS IS" BASIS,
     WITHOUT WARRANTIES OR CONDITIONS OF ANY KIND, either express or implied.
     See the License for the specific language governing permissions and
     limitations under the License.
-->

<robot xmlns:xacro="http://www.ros.org/wiki/xacro">
    <!-- <xacro:include filename="$(find uuv_descriptions)/urdf/common.urdf.xacro"/> -->

    <!-- Transmission Macro -->
    <xacro:macro name="simple_transmission" params="joint">
      <transmission name="${joint}_trans">
        <type>transmission_interface/SimpleTransmission</type>
        <joint name="${joint}">
          <hardwareInterface>EffortJointInterface</hardwareInterface>
        </joint>
        <actuator name="${joint}_motor">
          <hardwareInterface>EffortJointInterface</hardwareInterface>
          <mechanicalReduction>1</mechanicalReduction>
        </actuator>
      </transmission>
    </xacro:macro>

    <xacro:macro name="gripper" params="namespace">
        
        <!-- base link -->
        <link name="gripper_link">
            <xacro:box_inertial mass="1.0"
                        x="0.2"
                        y="0.05"
                        z="0.05">
            <origin xyz="0 0 0" rpy="0 0 0"/>
            </xacro:box_inertial>

            <visual>
                <origin xyz="0 0 0" rpy="0 0 0"/>
                <geometry>
                    <mesh filename="file://$(find gripper_description)/meshes/visual/base_link.dae" scale="1.0 1.0 1.0"/>
                </geometry>
            </visual>

            <collision>
                <origin xyz="0 0 0" rpy="0 0 0"/>
                <geometry>
                    <mesh filename="file://$(find gripper_description)/meshes/collision/base_link.dae" scale="1.0 1.0 1.0"/>
                </geometry>
            </collision>
        </link>


        <link name="left_jaw">
            <xacro:box_inertial mass="0.5"
                        x="0.1"
                        y="0.03"
                        z="0.1">
            <origin xyz="0 0 0" rpy="0 0 0"/>
            </xacro:box_inertial>

            <visual>
                <origin xyz="0 0 0" rpy="0 0 0"/>
                <geometry>
                    <mesh filename="file://$(find gripper_description)/meshes/visual/left_jaw.dae" scale="1.0 1.0 1.0"/>
                </geometry>
            </visual>

            <collision>
                <origin xyz="0 0 0" rpy="0 0 0"/>
                <geometry>
                    <mesh filename="file://$(find gripper_description)/meshes/collision/left_jaw.dae" scale="1.0 1.0 1.0"/>
                </geometry>
            </collision>
        </link>

        <joint name="gripper_link_to_left_jaw" type="revolute">
            <parent link="gripper_link"/>
            <child link="left_jaw"/>
            <origin xyz="0.15 0.03 0.0" rpy="0 0 0"/>
            <axis xyz="0 0 1"/>
            <limit lower="-1.00" upper="1.00" effort="50" velocity="0.14"/>
        </joint>

        <xacro:simple_transmission joint="gripper_link_to_left_jaw" />

        <link name="right_jaw">
            <xacro:box_inertial mass="0.5"
                        x="0.1"
                        y="0.03"
                        z="0.1">
            <origin xyz="0 0 0" rpy="0 0 0"/>
            </xacro:box_inertial>

            <visual>
                <origin xyz="0 0 0" rpy="0 0 0"/>
                <geometry>
                    <mesh filename="file://$(find gripper_description)/meshes/visual/right_jaw.dae" scale="1.0 1.0 1.0"/>
                </geometry>
            </visual>

            <collision>
                <origin xyz="0 0 0" rpy="0 0 0"/>
                <geometry>
                    <mesh filename="file://$(find gripper_description)/meshes/collision/right_jaw.dae" scale="1.0 1.0 1.0"/>
                </geometry>
            </collision>
        </link>

        <joint name="gripper_link_to_right_jaw" type="revolute">
            <parent link="gripper_link"/>
            <child link="right_jaw"/>
            <origin xyz="0.15 -0.03 0.0" rpy="0 0 0"/>
            <axis xyz="0 0 1"/>
            <limit lower="-1.0" upper="1.0" effort="50" velocity="0.14"/>
        </joint>

        <xacro:simple_transmission joint="gripper_link_to_right_jaw" />

        
    
    </xacro:macro>
        
</robot>
